Workbook

Sheet How to use
A1: MES Matters social calendar
A3: Newsletter start date (first Tuesday) | B3: 46322
A5: How it works
A6: Every week features one MES Matters article. The newsletter sends it on Tuesday morning, and four posts per platform support it.
A7: Tuesday: the article post. LinkedIn link goes in the first comment, not the post.
A8: Monday, Thursday and Friday: supporting posts on the same theme, with no link.
A9: Write each post once, then adapt it for each platform using the LinkedIn, X and Instagram columns.
A10: Story posts are prompts: use your own real experience. Anonymise customers and companies.
A12: What to edit
A13: Change the start date above and every date in the calendar moves with it.
A14: In the Calendar tab, update Status and Notes as you go. Everything else is the plan.
A16: Status
A17: Planned: topic agreed, not written yet
A18: Drafted: copy written for all three platforms
... A26: Week 1, Tue: Hook 'Your operators don't need another app. They need fewer.' Status: Drafted. Notes: 'Carousel designed, LinkedIn copy approved.'

Sheet Calendar
A1: Week | B1: Date | C1: Day | D1: Featured article | E1: Pillar | F1: Post type | G1: Hook (first line) | H1: Key points | I1: LinkedIn | J1: X | K1: Instagram | L1: Link | M1: Post order | N1: Status | O1: Notes
A2: 1 | B2: ='Weekly overview'!$B$2+(-1) | C2: Mon | D2: Connected worker: why your operators need one app, not five | E2: Smart Factory & AI | F2: Stat or framework | G2: 72% of industrial organisations say frontline workforce issues have hurt their operational performance. | H2: • Source: LNS Research, 2023 (in the article) • The problem isn't effort. It's tools that don't talk to each other. Ask: how many screens does your operator touch in one shift? | I2: Image or document carousel. No link. | J2: Single post with the image. | K2: Carousel, 5–7 slides. | L2: No link (keeps reach up) | M2: 1 | N2: Drafted | O2: Copy in 'Social posts: weeks 1–4' doc; images on the carousels page
A3: 1 | B3: ='Weekly overview'!$B$2+(0) | C3: Tue | D3: Connected worker: why your operators need one app, not five | E3: Smart Factory & AI | F3: Article post | G3: Your operators don't need another app. They need fewer. | H3: • Connected worker solves real frontline problems: skills, checklists, handover, instructions • Bought standalone, it becomes app number five on the operator's screen • It belongs inside MES/MOM, on the same data as production • Article: what it is, why now, and the word of caution | I3: Text post, 150–250 words. Article link in the FIRST COMMENT. | J3: Thread, 5–7 posts. Link in the last post. | K3: Carousel, 7–9 slides. 'Link in bio' on the last slide. | L3: https://www.mesmatters.com/post/connected-worker-one-app-not-five | M3: 2 | N3: Drafted | O3: Copy in 'Social posts: weeks 1–4' doc; images on the carousels page
A4: 1 | B4: ='Weekly overview'!$B$2+(2) | C4: Thu | D4: Connected worker: why your operators need one app, not five | E4: Smart Factory & AI | F4: Question / poll | G4: How many different apps does an operator in your factory use in a single shift? | H4: • Poll options: 1–2 / 3–4 / 5+ / I've never counted • Follow up in comments with why it matters: every switch loses context | I4: LinkedIn poll (1 week). Reply to comments. | J4: Poll. | K4: Story poll, plus a quote graphic in the feed. | L4: No link (keeps reach up) | M4: 3 | N4: Drafted | O4: Copy in 'Social posts: weeks 1–4' doc; images on the carousels page
A5: 1 | B5: ='Weekly overview'!$B$2+(3) | C5: Fri | D5: Connected worker: why your operators need one app, not five | E5: Smart Factory & AI | F5: Contrarian take | G5: A connected worker platform that duplicates your MES isn't digital transformation. It's a new silo with a nicer UI. | H5: • Two systems, two versions of the truth about the same shift • Integration costs land later, and they land on IT. Better question: what does the operator need on one screen? | I5: Short text post, 50–120 words. No link. | J5: Single post. | K5: Carousel: the take on slide 1, the reasoning over 3–4 slides. | L5: No link (keeps reach up) | M5: 4 | N5: Drafted | O5: Copy in 'Social posts: weeks 1–4' doc; images on the carousels page
A6: 2 | B6: ='Weekly overview'!$B$3+(-1) | C6: Mon | D6: What is a smart factory? No version number required | E6: Smart Factory & AI | F6: Myth vs reality | G6: Myth: a smart factory is full of robots and empty of people. | H6: • Reality: the smartest factories I've seen are full of people making better decisions • Automation matters, but data and process matter first. Carousel: 4 myths vs reality | I6: Text post or document carousel. No link. | J6: Single post. | K6: Carousel: myth slide, reality slide. | L6: No link (keeps reach up) | M6: 1 | N6: Drafted | O6: Copy in 'Social posts: weeks 1–4' doc; images on the carousels page
A7: 2 | B7: ='Weekly overview'!$B$3+(0) | C7: Tue | D7: What is a smart factory? No version number required | E7: Smart Factory & AI | F7: Article post | G7: A smart factory doesn't need a version number. | H7: • It's not Industry 6.0 or science fiction • It's people, processes and technology working together on good data • Five things define it, and none of them is a robot • It doesn't reduce complexity. It helps you manage it | I7: Text post, 150–250 words. Article link in the FIRST COMMENT. | J7: Thread, 5–7 posts. Link in the last post. | K7: Carousel, 7–9 slides. 'Link in bio' on the last slide. | L7: https://www.mesmatters.com/post/what-is-a-smart-factory | M7: 2 | N7: Drafted | O7: Copy in 'Social posts: weeks 1–4' doc; images on the carousels page
A8: 2 | B8: ='Weekly overview'!$B$3+(2) | C8: Thu | D8: What is a smart factory? No version number required | E8: Smart Factory & AI | F8: Stat or framework | G8: Deloitte asked 600 large manufacturers what smart manufacturing delivered. The headline: production output up 10–20% on average. | H8: • Deloitte 2025 Smart Manufacturing Survey (in the article) • These are averages from large companies, self-reported. The point: the returns are real when the basics are in place | I8: Image or document carousel. No link. | J8: Single post with the image. | K8: Carousel, 5–7 slides. | L8: No link (keeps reach up) | M8: 3 | N8: Drafted | O8: Copy in 'Social posts: weeks 1–4' doc; images on the carousels page
A9: 2 | B9: ='Weekly overview'!$B$3+(3) | C9: Fri | D9: What is a smart factory? No version number required | E9: Smart Factory & AI | F9: Story (your experience) | G9: Story prompt: the moment you realised a factory was 'smart' (or wasn't). | H9: • Your experience: a visit, a project, a conversation on the shopfloor • What gave it away? Data on screens, or people chasing paper?. End: what would you look for on a factory tour? | I9: Story post, 150–250 words, from your own experience. No link. | J9: Short thread, 3–4 posts. | K9: Reel: 30–45 sec talking to camera. | L9: No link (keeps reach up) | M9: 4 | N9: Drafted | O9: Copy in 'Social posts: weeks 1–4' doc; images on the carousels page
A10: 3 | B10: ='Weekly overview'!$B$4+(-1) | C10: Mon | D10: AI, ML and GenAI on the shopfloor: what each one actually does | E10: Smart Factory & AI | F10: Analogy | G10: Machine learning is older than you think. SPC has been spotting drift on production lines for decades. | H10: • Learn what normal looks like, then flag what isn't • That's the core idea behind a lot of 'AI' being sold today. Point: don't let the label distract you from the data | I10: Short text post, 50–120 words. No link. | J10: Single post. | K10: Quote graphic. | L10: No link (keeps reach up) | M10: 1 | N10: Drafted | O10: Copy in 'Social posts: weeks 1–4' doc; images on the carousels page
A11: 3 | B11: ='Weekly overview'!$B$4+(0) | C11: Tue | D11: AI, ML and GenAI on the shopfloor: what each one actually does | E11: Smart Factory & AI | F11: Article post | G11: AI, ML and GenAI are not the same thing. Using them interchangeably costs money. | H11: • Machine learning: predicting outcomes from your operational data • Generative AI: creating text, summaries and answers • Agentic AI: systems that take actions • All of them need the same thing first: clean, contextualised data | I11: Text post, 150–250 words. Article link in the FIRST COMMENT. | J11: Thread, 5–7 posts. Link in the last post. | K11: Carousel, 7–9 slides. 'Link in bio' on the last slide. | L11: https://www.mesmatters.com/post/ai-ml-genai-on-the-shopfloor | M11: 2 | N11: Drafted | O11: Copy in 'Social posts: weeks 1–4' doc; images on the carousels page
A12: 3 | B12: ='Weekly overview'!$B$4+(2) | C12: Thu | D12: AI, ML and GenAI on the shopfloor: what each one actually does | E12: Smart Factory & AI | F12: Question / poll | G12: Which AI use case would you fund first in your factory? | H12: • Poll: predictive maintenance / predictive quality / GenAI assistant for operators / natural-language reporting • Comment with what's stopping you | I12: LinkedIn poll (1 week). Reply to comments. | J12: Poll. | K12: Story poll, plus a quote graphic in the feed. | L12: No link (keeps reach up) | M12: 3 | N12: Drafted | O12: Copy in 'Social posts: weeks 1–4' doc; images on the carousels page
A13: 3 | B13: ='Weekly overview'!$B$4+(3) | C13: Fri | D13: AI, ML and GenAI on the shopfloor: what each one actually does | E13: Smart Factory & AI | F13: Contrarian take | G13: If your shopfloor data is typed in at the end of the shift, your AI project is a very expensive guess. | H13: • Models learn from what you feed them • Estimates in, confident-looking nonsense out. Fix the data capture first, then talk about models | I13: Short text post, 50–120 words. No link. | J13: Single post. | K13: Carousel: the take on slide 1, the reasoning over 3–4 slides. | L13: No link (keeps reach up) | M13: 4 | N13: Drafted | O13: Copy in 'Social posts: weeks 1–4' doc; images on the carousels page
A14: 4 | B14: ='Weekly overview'!$B$5+(-1) | C14: Mon | D14: The smart manufacturing maturity model: you can't skip a level | E14: Smart Factory & AI | F14: Checklist | G14: Four questions to find your factory's real maturity level. | H14: • Is production data captured automatically or typed in later? • Do production, quality and maintenance use the same data? • Can you trace a lot in minutes? • Do decisions use real-time data or last week's report? • Carousel: one slide per level | I14: Document carousel (PDF), one item per page. | J14: Thread, one item per post. | K14: Carousel, one item per slide. | L14: No link (keeps reach up) | M14: 1 | N14: Drafted | O14: Copy in 'Social posts: weeks 1–4' doc; images on the carousels page
A15: 4 | B15: ='Weekly overview'!$B$5+(0) | C15: Tue | D15: The smart manufacturing maturity model: you can't skip a level | E15: Smart Factory & AI | F15: Article post | G15: You can't skip a level of smart manufacturing maturity. Most factories are trying to. | H15: • Five levels from paper-driven to AI-enabled • Most factories sit between levels 1 and 3 • AI starts paying back around level 4, not before • Use the model to decide your next step, not your end state | I15: Text post, 150–250 words. Article link in the FIRST COMMENT. | J15: Thread, 5–7 posts. Link in the last post. | K15: Carousel, 7–9 slides. 'Link in bio' on the last slide. | L15: https://www.mesmatters.com/post/smart-manufacturing-maturity-model | M15: 2 | N15: Drafted | O15: Copy in 'Social posts: weeks 1–4' doc; images on the carousels page
A16: 4 | B16: ='Weekly overview'!$B$5+(2) | C16: Thu | D16: The smart manufacturing maturity model: you can't skip a level | E16: Smart Factory & AI | F16: Question / poll | G16: Be honest: what maturity level is your factory at today? | H16: • Poll: 1 Paper / 2 Spreadsheets / 3 Systems in silos / 4 Joined-up data • Comment: what's blocking the next step? | I16: LinkedIn poll (1 week). Reply to comments. | J16: Poll. | K16: Story poll, plus a quote graphic in the feed. | L16: No link (keeps reach up) | M16: 3 | N16: Drafted | O16: Copy in 'Social posts: weeks 1–4' doc; images on the carousels page
A17: 4 | B17: ='Weekly overview'!$B$5+(3) | C17: Fri | D17: The smart manufacturing maturity model: you can't skip a level | E17: Smart Factory & AI | F17: Contrarian take | G17: Buying AI before you've fixed your data is like fitting a turbo to a car with flat tyres. | H17: • Each level builds on the one before • Skipping ahead means paying twice. Where would your money go further this year? | I17: Short text post, 50–120 words. No link. | J17: Single post. | K17: Carousel: the take on slide 1, the reasoning over 3–4 slides. | L17: No link (keeps reach up) | M17: 4 | N17: Drafted | O17: Copy in 'Social posts: weeks 1–4' doc; images on the carousels page
A18: 5 | B18: ='Weekly overview'!$B$6+(-1) | C18: Mon | D18: PLM, ERP and MES: where the digital thread actually runs | E18: Foundations | F18: Stat or framework | G18: The digital thread in one picture: PLM → ERP → MES/MOM → service, and back again. | H18: • Graphic: who owns what at each step • The return path is the one most companies forget. Carousel version for Instagram | I18: Image or document carousel. No link. | J18: Single post with the image. | K18: Carousel, 5–7 slides. | L18: No link (keeps reach up) | M18: 1 | N18: Planned
A19: 5 | B19: ='Weekly overview'!$B$6+(0) | C19: Tue | D19: PLM, ERP and MES: where the digital thread actually runs | E19: Foundations | F19: Article post | G19: Everyone talks about the digital thread. Few can tell you where it actually runs. | H19: • PLM owns the product definition • ERP owns orders, cost and supply • MES/MOM owns how it's actually made, and the as-built record • ERP usually sits in the middle, and the hard part is engineering changes | I19: Text post, 150–250 words. Article link in the FIRST COMMENT. | J19: Thread, 5–7 posts. Link in the last post. | K19: Carousel, 7–9 slides. 'Link in bio' on the last slide. | L19: https://www.mesmatters.com/post/plm-erp-mes-digital-thread | M19: 2 | N19: Planned
A20: 5 | B20: ='Weekly overview'!$B$6+(2) | C20: Thu | D20: PLM, ERP and MES: where the digital thread actually runs | E20: Foundations | F20: Question / poll | G20: Does engineering change data reach your operators before or after the first wrong part? | H20: • Poll: before / same day / after / we find out from quality • Comment: how do changes reach your line today? | I20: LinkedIn poll (1 week). Reply to comments. | J20: Poll. | K20: Story poll, plus a quote graphic in the feed. | L20: No link (keeps reach up) | M20: 3 | N20: Planned
A21: 5 | B21: ='Weekly overview'!$B$6+(3) | C21: Fri | D21: PLM, ERP and MES: where the digital thread actually runs | E21: Foundations | F21: Contrarian take | G21: A direct PLM to MES link isn't always the answer. Sometimes ERP in the middle is exactly right. | H21: • Direct links make sense for complex, fast-changing products • For most, ERP holds effectivity and keeps everyone aligned. Choose based on change frequency, not fashion | I21: Short text post, 50–120 words. No link. | J21: Single post. | K21: Carousel: the take on slide 1, the reasoning over 3–4 slides. | L21: No link (keeps reach up) | M21: 4 | N21: Planned
A22: 6 | B22: ='Weekly overview'!$B$7+(-1) | C22: Mon | D22: Shift handover is a process. Treat it like one. | E22: Smart Factory & AI | F22: Story (your experience) | G22: Story prompt: the worst handover you've ever seen, and what it cost. | H22: • Your experience: a missed issue, a repeated fault, a safety near-miss • What information was missing?. End: what does good look like in your plant? | I22: Story post, 150–250 words, from your own experience. No link. | J22: Short thread, 3–4 posts. | K22: Reel: 30–45 sec talking to camera. | L22: No link (keeps reach up) | M22: 1 | N22: Planned
A23: 6 | B23: ='Weekly overview'!$B$7+(0) | C23: Tue | D23: Shift handover is a process. Treat it like one. | E23: Smart Factory & AI | F23: Article post | G23: Shift handover is a process. Most factories treat it like a chat at the door. | H23: • Verbal handovers lose detail and the next crew starts blind • A good handover answers a handful of specific questions • Build it from real data, structured, not just typed • Start this week, even before you change systems | I23: Text post, 150–250 words. Article link in the FIRST COMMENT. | J23: Thread, 5–7 posts. Link in the last post. | K23: Carousel, 7–9 slides. 'Link in bio' on the last slide. | L23: https://www.mesmatters.com/post/digital-shift-handover | M23: 2 | N23: Planned
A24: 6 | B24: ='Weekly overview'!$B$7+(2) | C24: Thu | D24: Shift handover is a process. Treat it like one. | E24: Smart Factory & AI | F24: Checklist | G24: Four questions every shift handover should answer. | H24: • What ran, and how did it perform? • What stopped, and is it fixed? • Any quality holds or open issues? • What's planned, and what's at risk? • Carousel: one question per slide | I24: Document carousel (PDF), one item per page. | J24: Thread, one item per post. | K24: Carousel, one item per slide. | L24: No link (keeps reach up) | M24: 3 | N24: Planned
A25: 6 | B25: ='Weekly overview'!$B$7+(3) | C25: Fri | D25: Shift handover is a process. Treat it like one. | E25: Smart Factory & AI | F25: Contrarian take | G25: A digital handover form that copies the paper one isn't a digital handover. | H25: • If people still retype what the system already knows, nothing improved • Pre-fill from production data, then add what only people know. Structure beats free text, every time | I25: Short text post, 50–120 words. No link. | J25: Single post. | K25: Carousel: the take on slide 1, the reasoning over 3–4 slides. | L25: No link (keeps reach up) | M25: 4 | N25: Planned
A26: 7 | B26: ='Weekly overview'!$B$8+(-1) | C26: Mon | D26: The smart factory tech stack, system by system | E26: Foundations | F26: Stat or framework | G26: The smart factory tech stack on one page. | H26: • Graphic: four layers, systems in each, arrows between them • Save it for your next architecture review. Carousel: one layer per slide | I26: Image or document carousel. No link. | J26: Single post with the image. | K26: Carousel, 5–7 slides. | L26: No link (keeps reach up) | M26: 1 | N26: Planned
A27: 7 | B27: ='Weekly overview'!$B$8+(0) | C27: Tue | D27: The smart factory tech stack, system by system | E27: Foundations | F27: Article post | G27: ERP, PLM, APS, MES, WMS, CMMS, LIMS, historians. Who does what? | H27: • The enterprise layer, the operations layer, the connectivity layer and the data layer • Where the boundaries sit, and why overlaps cost money • Questions to ask about every system you own • The article walks through it system by system | I27: Text post, 150–250 words. Article link in the FIRST COMMENT. | J27: Thread, 5–7 posts. Link in the last post. | K27: Carousel, 7–9 slides. 'Link in bio' on the last slide. | L27: https://www.mesmatters.com/post/smart-factory-tech-stack | M27: 2 | N27: Planned
A28: 7 | B28: ='Weekly overview'!$B$8+(2) | C28: Thu | D28: The smart factory tech stack, system by system | E28: Foundations | F28: Question / poll | G28: Which boundary causes the most arguments in your organisation? | H28: • Poll: ERP vs MES / MES vs WMS / MES vs CMMS / MES vs QMS • Comment with your war story | I28: LinkedIn poll (1 week). Reply to comments. | J28: Poll. | K28: Story poll, plus a quote graphic in the feed. | L28: No link (keeps reach up) | M28: 3 | N28: Planned
A29: 7 | B29: ='Weekly overview'!$B$8+(3) | C29: Fri | D29: The smart factory tech stack, system by system | E29: Foundations | F29: Contrarian take | G29: You don't need every acronym in the stack. You need clear ownership of every piece of data. | H29: • Two systems owning the same data is where projects go wrong • Decide the system of record before you buy. Fewer systems, clearer boundaries | I29: Short text post, 50–120 words. No link. | J29: Single post. | K29: Carousel: the take on slide 1, the reasoning over 3–4 slides. | L29: No link (keeps reach up) | M29: 4 | N29: Planned
A30: 8 | B30: ='Weekly overview'!$B$9+(-1) | C30: Mon | D30: MES vs MOM: why the difference matters when you buy | E30: Foundations | F30: Analogy | G30: MES is one instrument. MOM is the orchestra. | H30: • Production on its own can sound great • But quality, inventory and maintenance have to play from the same score. Separate systems per pillar means four conductors | I30: Short text post, 50–120 words. No link. | J30: Single post. | K30: Quote graphic. | L30: No link (keeps reach up) | M30: 1 | N30: Planned
A31: 8 | B31: ='Weekly overview'!$B$9+(0) | C31: Tue | D31: MES vs MOM: why the difference matters when you buy | E31: Foundations | F31: Article post | G31: MES and MOM are used interchangeably. They shouldn't be, especially when you're buying. | H31: • MES is production execution: orders, counts, scrap, downtime, OEE • MOM covers production, quality, inventory and maintenance • The value is everyone working on the same data • The risk: a different system per pillar, stitched together | I31: Text post, 150–250 words. Article link in the FIRST COMMENT. | J31: Thread, 5–7 posts. Link in the last post. | K31: Carousel, 7–9 slides. 'Link in bio' on the last slide. | L31: https://www.mesmatters.com/post/mes-vs-mom | M31: 2 | N31: Planned
A32: 8 | B32: ='Weekly overview'!$B$9+(2) | C32: Thu | D32: MES vs MOM: why the difference matters when you buy | E32: Foundations | F32: Question / poll | G32: How many systems run production, quality, inventory and maintenance in your factory? | H32: • Poll: 1 / 2 / 3–4 / More than 4 • Comment: where does data fall between the cracks? | I32: LinkedIn poll (1 week). Reply to comments. | J32: Poll. | K32: Story poll, plus a quote graphic in the feed. | L32: No link (keeps reach up) | M32: 3 | N32: Planned
A33: 8 | B33: ='Weekly overview'!$B$9+(3) | C33: Fri | D33: MES vs MOM: why the difference matters when you buy | E33: Foundations | F33: Checklist | G33: Four questions to ask any vendor who says they 'do MOM'. | H33: • Which pillars are native, and which are partner products? • Is it one data model or several integrated ones? • Can a quality hold stop a production order instantly? • Show me, don't tell me | I33: Document carousel (PDF), one item per page. | J33: Thread, one item per post. | K33: Carousel, one item per slide. | L33: No link (keeps reach up) | M33: 4 | N33: Planned
A34: 9 | B34: ='Weekly overview'!$B$10+(-1) | C34: Mon | D34: EBOM, MBOM, as-built: who owns the BOM at each stage | E34: Foundations | F34: Stat or framework | G34: EBOM → MBOM → order BOM → as-built. One graphic, four owners. | H34: • Graphic: the BOM's journey from engineering to shipment • Label the system of record at each stage. Carousel for Instagram | I34: Image or document carousel. No link. | J34: Single post with the image. | K34: Carousel, 5–7 slides. | L34: No link (keeps reach up) | M34: 1 | N34: Planned
A35: 9 | B35: ='Weekly overview'!$B$10+(0) | C35: Tue | D35: EBOM, MBOM, as-built: who owns the BOM at each stage | E35: Foundations | F35: Article post | G35: A bill of materials changes shape four times before a product ships. Who owns it at each stage? | H35: • EBOM in PLM, MBOM in ERP, order BOM for the job, as-built in MES/MOM • Problems start where ownership is unclear • The as-built record is the one you'll need in a recall • Article: who owns what, and where it goes wrong | I35: Text post, 150–250 words. Article link in the FIRST COMMENT. | J35: Thread, 5–7 posts. Link in the last post. | K35: Carousel, 7–9 slides. 'Link in bio' on the last slide. | L35: https://www.mesmatters.com/post/ebom-mbom-as-built | M35: 2 | N35: Planned
A36: 9 | B36: ='Weekly overview'!$B$10+(2) | C36: Thu | D36: EBOM, MBOM, as-built: who owns the BOM at each stage | E36: Foundations | F36: Question / poll | G36: Where does BOM data go wrong most often in your business? | H36: • Poll: EBOM to MBOM / MBOM to order / order to as-built / we don't capture as-built • Comment with an example | I36: LinkedIn poll (1 week). Reply to comments. | J36: Poll. | K36: Story poll, plus a quote graphic in the feed. | L36: No link (keeps reach up) | M36: 3 | N36: Planned
A37: 9 | B37: ='Weekly overview'!$B$10+(3) | C37: Fri | D37: EBOM, MBOM, as-built: who owns the BOM at each stage | E37: Foundations | F37: Contrarian take | G37: If you can't produce an as-built record in minutes, you don't have traceability. You have a parts list. | H37: • What was planned and what was built are different things • Substitutions, rework and serial numbers live in MES/MOM. Ask: how long would a recall investigation take today? | I37: Short text post, 50–120 words. No link. | J37: Single post. | K37: Carousel: the take on slide 1, the reasoning over 3–4 slides. | L37: No link (keeps reach up) | M37: 4 | N37: Planned
A38: 10 | B38: ='Weekly overview'!$B$11+(-1) | C38: Mon | D38: Raw machine data is worthless. Context is what makes it useful | E38: Smart Factory & AI | F38: Analogy | G38: A machine signal without context is like a heart rate without knowing if someone is sleeping or sprinting. | H38: • Same number, completely different meaning • MES/MOM adds the 'what was happening' around every signal. That's the difference between data and a decision | I38: Short text post, 50–120 words. No link. | J38: Single post. | K38: Quote graphic. | L38: No link (keeps reach up) | M38: 1 | N38: Planned
A39: 10 | B39: ='Weekly overview'!$B$11+(0) | C39: Tue | D39: Raw machine data is worthless. Context is what makes it useful | E39: Smart Factory & AI | F39: Article post | G39: Raw machine data is worthless. Context is what makes it useful. | H39: • A signal that says 'stopped' tells you nothing on its own • Order, product, operator, reason and tool turn it into information • Point solutions lose that context at every boundary • Context is also what AI really needs | I39: Text post, 150–250 words. Article link in the FIRST COMMENT. | J39: Thread, 5–7 posts. Link in the last post. | K39: Carousel, 7–9 slides. 'Link in bio' on the last slide. | L39: https://www.mesmatters.com/post/contextualised-manufacturing-data | M39: 2 | N39: Planned
A40: 10 | B40: ='Weekly overview'!$B$11+(2) | C40: Thu | D40: Raw machine data is worthless. Context is what makes it useful | E40: Smart Factory & AI | F40: Stat or framework | G40: From signal to decision in four steps. | H40: • Signal: Machine 3 stopped • Context: order 4471, tool T-114, night shift • Insight: the same tool causes most rejects • Decision: replace the tool. Carousel walk-through | I40: Image or document carousel. No link. | J40: Single post with the image. | K40: Carousel, 5–7 slides. | L40: No link (keeps reach up) | M40: 3 | N40: Planned
...

Sheet Weekly overview
A1: Week | B1: Tuesday | C1: Featured article | D1: Pillar | E1: Article link | F1: Posts done (of 4)
A2: 1 | B2: ='How to use'!$B$3+0 | C2: Connected worker: why your operators need one app, not five | D2: Smart Factory & AI | E2: https://www.mesmatters.com/post/connected-worker-one-app-not-five | F2: =COUNTIFS(Calendar!$A:$A,A2,Calendar!$N:$N,"Posted")
A3: 2 | B3: ='How to use'!$B$3+7 | C3: What is a smart factory? No version number required | D3: Smart Factory & AI | E3: https://www.mesmatters.com/post/what-is-a-smart-factory | F3: =COUNTIFS(Calendar!$A:$A,A3,Calendar!$N:$N,"Posted")
A4: 3 | B4: ='How to use'!$B$3+14 | C4: AI, ML and GenAI on the shopfloor: what each one actually does | D4: Smart Factory & AI | E4: https://www.mesmatters.com/post/ai-ml-genai-on-the-shopfloor | F4: =COUNTIFS(Calendar!$A:$A,A4,Calendar!$N:$N,"Posted")
A5: 4 | B5: ='How to use'!$B$3+21 | C5: The smart manufacturing maturity model: you can't skip a level | D5: Smart Factory & AI | E5: https://www.mesmatters.com/post/smart-manufacturing-maturity-model | F5: =COUNTIFS(Calendar!$A:$A,A5,Calendar!$N:$N,"Posted")
A6: 5 | B6: ='How to use'!$B$3+28 | C6: PLM, ERP and MES: where the digital thread actually runs | D6: Foundations | E6: https://www.mesmatters.com/post/plm-erp-mes-digital-thread | F6: =COUNTIFS(Calendar!$A:$A,A6,Calendar!$N:$N,"Posted")
A7: 6 | B7: ='How to use'!$B$3+35 | C7: Shift handover is a process. Treat it like one. | D7: Smart Factory & AI | E7: https://www.mesmatters.com/post/digital-shift-handover | F7: =COUNTIFS(Calendar!$A:$A,A7,Calendar!$N:$N,"Posted")
A8: 7 | B8: ='How to use'!$B$3+42 | C8: The smart factory tech stack, system by system | D8: Foundations | E8: https://www.mesmatters.com/post/smart-factory-tech-stack | F8: =COUNTIFS(Calendar!$A:$A,A8,Calendar!$N:$N,"Posted")
A9: 8 | B9: ='How to use'!$B$3+49 | C9: MES vs MOM: why the difference matters when you buy | D9: Foundations | E9: https://www.mesmatters.com/post/mes-vs-mom | F9: =COUNTIFS(Calendar!$A:$A,A9,Calendar!$N:$N,"Posted")
A10: 9 | B10: ='How to use'!$B$3+56 | C10: EBOM, MBOM, as-built: who owns the BOM at each stage | D10: Foundations | E10: https://www.mesmatters.com/post/ebom-mbom-as-built | F10: =COUNTIFS(Calendar!$A:$A,A10,Calendar!$N:$N,"Posted")
A11: 10 | B11: ='How to use'!$B$3+63 | C11: Raw machine data is worthless. Context is what makes it useful | D11: Smart Factory & AI | E11: https://www.mesmatters.com/post/contextualised-manufacturing-data | F11: =COUNTIFS(Calendar!$A:$A,A11,Calendar!$N:$N,"Posted")
A12: 11 | B12: ='How to use'!$B$3+70 | C12: How to build an MES business case leadership will sign | D12: Implementation | E12: https://www.mesmatters.com/post/mes-business-case | F12: =COUNTIFS(Calendar!$A:$A,A12,Calendar!$N:$N,"Posted")
A13: 12 | B13: ='How to use'!$B$3+77 | C13: The biggest barriers to MES success in food manufacturing | D13: Implementation | E13: https://www.mesmatters.com/post/food-manufacturing-mes-barriers | F13: =COUNTIFS(Calendar!$A:$A,A13,Calendar!$N:$N,"Posted")
A14: 13 | B14: ='How to use'!$B$3+84 | C14: From CPQ to the shopfloor: building what the customer actually configured | D14: Foundations | E14: https://www.mesmatters.com/post/cpq-to-shopfloor | F14: =COUNTIFS(Calendar!$A:$A,A14,Calendar!$N:$N,"Posted")
A15: 14 | B15: ='How to use'!$B$3+91 | C15: Skills you can enforce, not just record | D15: Smart Factory & AI | E15: https://www.mesmatters.com/post/skills-enforcement-shopfloor | F15: =COUNTIFS(Calendar!$A:$A,A15,Calendar!$N:$N,"Posted")
A16: 15 | B16: ='How to use'!$B$3+98 | C16: Practical GenAI for the shopfloor: four uses that save time today | D16: Smart Factory & AI | E16: https://www.mesmatters.com/post/practical-genai-for-the-shopfloor | F16: =COUNTIFS(Calendar!$A:$A,A16,Calendar!$N:$N,"Posted")
A17: 16 | B17: ='How to use'!$B$3+105 | C17: WMS, MES and ERP: who owns inventory once it reaches the line? | D17: Foundations | E17: https://www.mesmatters.com/post/wms-vs-mes-inventory | F17: =COUNTIFS(Calendar!$A:$A,A17,Calendar!$N:$N,"Posted")
A18: 17 | B18: ='How to use'!$B$3+112 | C18: IIoT doesn't replace MES. Here's why. | D18: Foundations | E18: https://www.mesmatters.com/post/iiot-vs-mes | F18: =COUNTIFS(Calendar!$A:$A,A18,Calendar!$N:$N,"Posted")
A19: 18 | B19: ='How to use'!$B$3+119 | C19: Configure, don't customise | D19: Implementation | E19: https://www.mesmatters.com/post/configure-dont-customise | F19: =COUNTIFS(Calendar!$A:$A,A19,Calendar!$N:$N,"Posted")
A20: 19 | B20: ='How to use'!$B$3+126 | C20: ERP, APS and MES scheduling: the plan versus the shift | D20: Foundations | E20: https://www.mesmatters.com/post/aps-vs-mes-scheduling | F20: =COUNTIFS(Calendar!$A:$A,A20,Calendar!$N:$N,"Posted")
A21: 20 | B21: ='How to use'!$B$3+133 | C21: Digital work instructions that know what's running | D21: Smart Factory & AI | E21: https://www.mesmatters.com/post/digital-work-instructions | F21: =COUNTIFS(Calendar!$A:$A,A21,Calendar!$N:$N,"Posted")
A22: 21 | B22: ='How to use'!$B$3+140 | C22: Predictive maintenance needs data you probably aren't collecting yet | D22: Smart Factory & AI | E22: https://www.mesmatters.com/post/predictive-maintenance-data | F22: =COUNTIFS(Calendar!$A:$A,A22,Calendar!$N:$N,"Posted")
A23: 22 | B23: ='How to use'!$B$3+147 | C23: QMS and MES: closing the quality loop | D23: Foundations | E23: https://www.mesmatters.com/post/qms-and-mes-quality | F23: =COUNTIFS(Calendar!$A:$A,A23,Calendar!$N:$N,"Posted")
A24: 23 | B24: ='How to use'!$B$3+154 | C24: Your traceability probably isn't as good as you think | D24: Foundations | E24: https://www.mesmatters.com/post/manufacturing-traceability | F24: =COUNTIFS(Calendar!$A:$A,A24,Calendar!$N:$N,"Posted")
A25: 24 | B25: ='How to use'!$B$3+161 | C25: How to choose an MES: 12 questions to ask every vendor | D25: Implementation | E25: https://www.mesmatters.com/post/how-to-choose-an-mes | F25: =COUNTIFS(Calendar!$A:$A,A25,Calendar!$N:$N,"Posted")
A26: 25 | B26: ='How to use'!$B$3+168 | C26: SPC on the shopfloor: catch the drift before it becomes scrap | D26: Foundations | E26: https://www.mesmatters.com/post/spc-on-the-shopfloor | F26: =COUNTIFS(Calendar!$A:$A,A26,Calendar!$N:$N,"Posted")
A27: 26 | B27: ='How to use'!$B$3+175 | C27: AI for the frontline: copilots, shift summaries and coaching | D27: Smart Factory & AI | E27: https://www.mesmatters.com/post/ai-for-frontline-workers | F27: =COUNTIFS(Calendar!$A:$A,A27,Calendar!$N:$N,"Posted")
A28: 27 | B28: ='How to use'!$B$3+182 | C28: Eight smart manufacturing myths that refuse to die | D28: Smart Factory & AI | E28: https://www.mesmatters.com/post/smart-manufacturing-myths | F28: =COUNTIFS(Calendar!$A:$A,A28,Calendar!$N:$N,"Posted")
A29: 28 | B29: ='How to use'!$B$3+189 | C29: EAM, CMMS and MES: who owns the maintenance work order? | D29: Foundations | E29: https://www.mesmatters.com/post/eam-cmms-and-mes | F29: =COUNTIFS(Calendar!$A:$A,A29,Calendar!$N:$N,"Posted")
A30: 29 | B30: ='How to use'!$B$3+196 | C30: MES functionality: maintenance | D30: Foundations | E30: https://www.mesmatters.com/post/mes-functionality-maintenance | F30: =COUNTIFS(Calendar!$A:$A,A30,Calendar!$N:$N,"Posted")
A31: 30 | B31: ='How to use'!$B$3+203 | C31: Resistance to change is guaranteed. Plan for it. | D31: Implementation | E31: https://www.mesmatters.com/post/manufacturing-change-management | F31: =COUNTIFS(Calendar!$A:$A,A31,Calendar!$N:$N,"Posted")
A32: 31 | B32: ='How to use'!$B$3+210 | C32: LIMS and MES: getting lab results to the line before the batch moves on | D32: Foundations | E32: https://www.mesmatters.com/post/lims-and-mes | F32: =COUNTIFS(Calendar!$A:$A,A32,Calendar!$N:$N,"Posted")
A33: 32 | B33: ='How to use'!$B$3+217 | C33: Agentic AI and MCP, explained for people who run factories | D33: Smart Factory & AI | E33: https://www.mesmatters.com/post/agentic-ai-mcp-manufacturing | F33: =COUNTIFS(Calendar!$A:$A,A33,Calendar!$N:$N,"Posted")
A34: 33 | B34: ='How to use'!$B$3+224 | C34: Manufacturing KPIs beyond OEE | D34: Foundations | E34: https://www.mesmatters.com/post/manufacturing-kpis-beyond-oee | F34: =COUNTIFS(Calendar!$A:$A,A34,Calendar!$N:$N,"Posted")
A35: 34 | B35: ='How to use'!$B$3+231 | C35: Connecting MES/MOM to everything else: integration patterns that last | D35: Implementation | E35: https://www.mesmatters.com/post/isa95-integration-patterns | F35: =COUNTIFS(Calendar!$A:$A,A35,Calendar!$N:$N,"Posted")
A36: 35 | B36: ='How to use'!$B$3+238 | C36: Six technology mistakes that sink smart factory projects | D36: Implementation | E36: https://www.mesmatters.com/post/smart-factory-technology-mistakes | F36: =COUNTIFS(Calendar!$A:$A,A36,Calendar!$N:$N,"Posted")
A37: 36 | B37: ='How to use'!$B$3+245 | C37: Digital twins run on shopfloor data. MES/MOM is where it comes from | D37: Smart Factory & AI | E37: https://www.shopfloormatters.com/post/mes-and-digital-twins | F37: =COUNTIFS(Calendar!$A:$A,A37,Calendar!$N:$N,"Posted")
A38: 37 | B38: ='How to use'!$B$3+252 | C38: OT cybersecurity for MES/MOM: what operations leaders need to know | D38: Implementation | E38: https://www.mesmatters.com/post/ot-cybersecurity-for-mes | F38: =COUNTIFS(Calendar!$A:$A,A38,Calendar!$N:$N,"Posted")
A39: 38 | B39: ='How to use'!$B$3+259 | C39: OPC UA, MQTT and UNS in plain English | D39: Foundations | E39: https://www.mesmatters.com/post/opc-ua-mqtt-uns-explained | F39: =COUNTIFS(Calendar!$A:$A,A39,Calendar!$N:$N,"Posted")
A40: 39 | B40: ='How to use'!$B$3+266 | C40: Your ERP master data isn't ready for MES | D40: Implementation | E40: https://www.mesmatters.com/post/erp-master-data-for-mes | F40: =COUNTIFS(Calendar!$A:$A,A40,Calendar!$N:$N,"Posted")
...

Sheet Post types
A1: Post type | B1: What it is | C1: LinkedIn | D1: X | E1: Instagram
A2: Article post | B2: The weekly anchor. Sells the featured article and drives people to the site and newsletter. | C2: Text post, 150–250 words. Article link in the FIRST COMMENT. | D2: Thread, 5–7 posts. Link in the last post. | E2: Carousel, 7–9 slides. 'Link in bio' on the last slide.
A3: Contrarian take | B3: A sharp opinion that challenges a common belief. Starts discussion. | C3: Short text post, 50–120 words. No link. | D3: Single post. | E3: Carousel: the take on slide 1, the reasoning over 3–4 slides.
A4: Story (your experience) | B4: A real moment from your own career that illustrates the theme. You write it; the calendar gives the prompt. | C4: Story post, 150–250 words, from your own experience. No link. | D4: Short thread, 3–4 posts. | E4: Reel: 30–45 sec talking to camera.
A5: Stat or framework | B5: One number or one framework, made visual. | C5: Image or document carousel. No link. | D5: Single post with the image. | E5: Carousel, 5–7 slides.
A6: Question / poll | B6: A question or poll that invites people to share their experience. | C6: LinkedIn poll (1 week). Reply to comments. | D6: Poll. | E6: Story poll, plus a quote graphic in the feed.
A7: Myth vs reality | B7: A common belief and why it's wrong. | C7: Text post or document carousel. No link. | D7: Single post. | E7: Carousel: myth slide, reality slide.
A8: Checklist | B8: A short list people save and come back to. | C8: Document carousel (PDF), one item per page. | D8: Thread, one item per post. | E8: Carousel, one item per slide.
A9: Analogy | B9: An everyday comparison that makes a technical idea click. | C9: Short text post, 50–120 words. No link. | D9: Single post. | E9: Quote graphic.
A11: Posts per type
A12: Article post | B12: =COUNTIF(Calendar!$F:$F,A12)
A13: Contrarian take | B13: =COUNTIF(Calendar!$F:$F,A13)
A14: Story (your experience) | B14: =COUNTIF(Calendar!$F:$F,A14)
A15: Stat or framework | B15: =COUNTIF(Calendar!$F:$F,A15)
A16: Question / poll | B16: =COUNTIF(Calendar!$F:$F,A16)
A17: Myth vs reality | B17: =COUNTIF(Calendar!$F:$F,A17)
A18: Checklist | B18: =COUNTIF(Calendar!$F:$F,A18)
A19: Analogy | B19: =COUNTIF(Calendar!$F:$F,A19)
A20: Total | B20: =SUM(B12:B19)
